BuildError
werkzeug.routing.exceptions.BuildError: Could not build url for endpoint 'admin'. Did you mean 'index' instead?

Traceback (most recent call last)
File "/home/runner/MyGPTApp/.pythonlibs/lib/python3.11/site-packages/flask/app.py", line 1498, in __call__
return self.wsgi_app(environ, start_response)
       ^^^^^^^^^^^^^^^^^^^^^^^^^^^^^^^^^^^^^^
File "/home/runner/MyGPTApp/.pythonlibs/lib/python3.11/site-packages/werkzeug/middleware/proxy_fix.py", line 183, in __call__
return self.app(environ, start_response)
       ^^^^^^^^^^^^^^^^^^^^^^^^^^^^^^^^^
File "/home/runner/MyGPTApp/.pythonlibs/lib/python3.11/site-packages/whitenoise/base.py", line 81, in __call__
return self.application(environ, start_response)
       ^^^^^^^^^^^^^^^^^^^^^^^^^^^^^^^^^^^^^^^^^
File "/home/runner/MyGPTApp/.pythonlibs/lib/python3.11/site-packages/flask/app.py", line 1476, in wsgi_app
response = self.handle_exception(e)
           ^^^^^^^^^^^^^^^^^^^^^^^^
File "/home/runner/MyGPTApp/.pythonlibs/lib/python3.11/site-packages/flask_cors/extension.py", line 194, in wrapped_function
return cors_after_request(app.make_response(f(*args, **kwargs)))
                                            ^^^^^^^^^^^^^^^^^^
File "/home/runner/MyGPTApp/.pythonlibs/lib/python3.11/site-packages/flask/app.py", line 1473, in wsgi_app
response = self.full_dispatch_request()
           ^^^^^^^^^^^^^^^^^^^^^^^^^^^^
File "/home/runner/MyGPTApp/.pythonlibs/lib/python3.11/site-packages/flask/app.py", line 882, in full_dispatch_request
rv = self.handle_user_exception(e)
     ^^^^^^^^^^^^^^^^^^^^^^^^^^^^^
File "/home/runner/MyGPTApp/.pythonlibs/lib/python3.11/site-packages/flask_cors/extension.py", line 194, in wrapped_function
return cors_after_request(app.make_response(f(*args, **kwargs)))
                                            ^^^^^^^^^^^^^^^^^^
File "/home/runner/MyGPTApp/.pythonlibs/lib/python3.11/site-packages/flask/app.py", line 880, in full_dispatch_request
rv = self.dispatch_request()
     ^^^^^^^^^^^^^^^^^^^^^^^
File "/home/runner/MyGPTApp/.pythonlibs/lib/python3.11/site-packages/flask/app.py", line 865, in dispatch_request
return self.ensure_sync(self.view_functions[rule.endpoint])(**view_args)  # type: ignore[no-any-return]
       ^^^^^^^^^^^^^^^^^^^^^^^^^^^^^^^^^^^^^^^^^^^^^^^^^^^^^^^^^^^^^^^^^
File "/home/runner/MyGPTApp/.pythonlibs/lib/python3.11/site-packages/flask_login/utils.py", line 290, in decorated_view
return current_app.ensure_sync(func)(*args, **kwargs)
       ^^^^^^^^^^^^^^^^^^^^^^^^^^^^^^^^^^^^^^^^^^^^^^
File "/home/runner/MyGPTApp/routes.py", line 140, in chat
return render_template('chat.html', chats=chats)
       ^^^^^^^^^^^^^^^^^^^^^^^^^^^^^^^^^^^^^^^^^
File "/home/runner/MyGPTApp/.pythonlibs/lib/python3.11/site-packages/flask/templating.py", line 150, in render_template
return _render(app, template, context)
       ^^^^^^^^^^^^^^^^^^^^^^^^^^^^^^^
File "/home/runner/MyGPTApp/.pythonlibs/lib/python3.11/site-packages/flask/templating.py", line 131, in _render
rv = template.render(context)
     ^^^^^^^^^^^^^^^^^^^^^^^^
File "/home/runner/MyGPTApp/.pythonlibs/lib/python3.11/site-packages/jinja2/environment.py", line 1304, in render
self.environment.handle_exception()
^^^^^^^^^^^^^^^^^^^^^^^^^^^^^^^^^^^
File "/home/runner/MyGPTApp/.pythonlibs/lib/python3.11/site-packages/jinja2/environment.py", line 939, in handle_exception
raise rewrite_traceback_stack(source=source)
^^^^^^^^^^^^^^^^^^^^^^^^^^^^^^^^^^^^^^^^^^^^
File "/home/runner/MyGPTApp/templates/chat.html", line 1, in top-level template code
{% extends "base.html" %}
File "/home/runner/MyGPTApp/templates/base.html", line 25, in top-level template code
<a class="nav-item nav-link" href="{{ url_for('admin') }}">Admin</a>
File "/home/runner/MyGPTApp/.pythonlibs/lib/python3.11/site-packages/flask/app.py", line 1084, in url_for
return self.handle_url_build_error(error, endpoint, values)
       ^^^^^^^^^^^^^^^^^^^^^^^^^^^^^^^^^^^^^^^^^^^^^^^^^^^^
File "/home/runner/MyGPTApp/.pythonlibs/lib/python3.11/site-packages/flask/app.py", line 1073, in url_for
rv = url_adapter.build(  # type: ignore[union-attr]
     
File "/home/runner/MyGPTApp/.pythonlibs/lib/python3.11/site-packages/werkzeug/routing/map.py", line 924, in build
raise BuildError(endpoint, values, method, self)
^^^^^^^^^^^^^^^^^^^^^^^^^^^^^^^^^^^^^^^^^^^^^^^^
werkzeug.routing.exceptions.BuildError: Could not build url for endpoint 'admin'. Did you mean 'index' instead?
The debugger caught an exception in your WSGI application. You can now look at the traceback which led to the error.
To switch between the interactive traceback and the plaintext one, you can click on the "Traceback" headline. From the text traceback you can also create a paste of it.