ERROR:app:Exception on /login [GET]
Traceback (most recent call last):
  File "/home/runner/DjangoGPTChatHistory/.pythonlibs/lib/python3.11/site-packages/flask/app.py", line 1473, in wsgi_app
    response = self.full_dispatch_request()
               ^^^^^^^^^^^^^^^^^^^^^^^^^^^^
  File "/home/runner/DjangoGPTChatHistory/.pythonlibs/lib/python3.11/site-packages/flask/app.py", line 882, in full_dispatch_request
    rv = self.handle_user_exception(e)
         ^^^^^^^^^^^^^^^^^^^^^^^^^^^^^
  File "/home/runner/DjangoGPTChatHistory/.pythonlibs/lib/python3.11/site-packages/flask/app.py", line 880, in full_dispatch_request
    rv = self.dispatch_request()
         ^^^^^^^^^^^^^^^^^^^^^^^
  File "/home/runner/DjangoGPTChatHistory/.pythonlibs/lib/python3.11/site-packages/flask/app.py", line 865, in dispatch_request
    return self.ensure_sync(self.view_functions[rule.endpoint])(**view_args)  # type: ignore[no-any-return]
           ^^^^^^^^^^^^^^^^^^^^^^^^^^^^^^^^^^^^^^^^^^^^^^^^^^^^^^^^^^^^^^^^^
  File "/home/runner/DjangoGPTChatHistory/routes.py", line 74, in login
    return render_template('login.html')
           ^^^^^^^^^^^^^^^^^^^^^^^^^^^^^
  File "/home/runner/DjangoGPTChatHistory/.pythonlibs/lib/python3.11/site-packages/flask/templating.py", line 150, in render_template
    return _render(app, template, context)
           ^^^^^^^^^^^^^^^^^^^^^^^^^^^^^^^
  File "/home/runner/DjangoGPTChatHistory/.pythonlibs/lib/python3.11/site-packages/flask/templating.py", line 131, in _render
    rv = template.render(context)
         ^^^^^^^^^^^^^^^^^^^^^^^^
  File "/home/runner/DjangoGPTChatHistory/.pythonlibs/lib/python3.11/site-packages/jinja2/environment.py", line 1304, in render
    self.environment.handle_exception()
  File "/home/runner/DjangoGPTChatHistory/.pythonlibs/lib/python3.11/site-packages/jinja2/environment.py", line 939, in handle_exception
    raise rewrite_traceback_stack(source=source)
  File "/home/runner/DjangoGPTChatHistory/templates/login.html", line 1, in top-level template code
    {% extends "base.html" %}
  File "/home/runner/DjangoGPTChatHistory/templates/base.html", line 44, in top-level template code
    {% block content %}{% endblock %}
    ^^^^^^^^^^^^^^^^^^^^^^^^^
  File "/home/runner/DjangoGPTChatHistory/templates/login.html", line 28, in block 'content'
    <a href="{{ url_for('forgot_password') }}">Forgot Password?</a>
    ^^^^^^^^^^^^^^^^^^^^^^^^^
  File "/home/runner/DjangoGPTChatHistory/.pythonlibs/lib/python3.11/site-packages/flask/app.py", line 1084, in url_for
    return self.handle_url_build_error(error, endpoint, values)
           ^^^^^^^^^^^^^^^^^^^^^^^^^^^^^^^^^^^^^^^^^^^^^^^^^^^^
  File "/home/runner/DjangoGPTChatHistory/.pythonlibs/lib/python3.11/site-packages/flask/app.py", line 1073, in url_for
    rv = url_adapter.build(  # type: ignore[union-attr]
         ^^^^^^^^^^^^^^^^^^^^^^^^^^^^^^^^^^^^^^^^^^^^^^
  File "/home/runner/DjangoGPTChatHistory/.pythonlibs/lib/python3.11/site-packages/werkzeug/routing/map.py", line 924, in build
    raise BuildError(endpoint, values, method, self)
werkzeug.routing.exceptions.BuildError: Could not build url for endpoint 'forgot_password'. Did you mean 'update_password' instead?
10.83.7.182 - - [26/Oct/2024:16:57:23 +0000] "GET /login?next=%2F HTTP/1.1" 500 265 "https://8fd35030-b652-40d7-a47f-0615ce5b5ec7-00-38hra4tt17d2o.janeway.replit.dev/__replco/workspace_iframe.html?initialPath=%2Flogin%3Fnext%3D%252F&id=%3Ar27%3A" "Mozilla/5.0 (Windows NT 10.0; Win64; x64) AppleWebKit/537.36 (KHTML, like Gecko) Chrome/130.0.0.0 Safari/537.36"
10.83.8.52 - - [26/Oct/2024:16:57:23 +0000] "GET /settings HTTP/1.1" 302 233 "-" "Mozilla/5.0 (X11; Linux x86_64) AppleWebKit/537.36 (KHTML, like Gecko) HeadlessChrome/118.0.5993.88 Safari/537.36"
ERROR:app:Exception on /login [GET]
Traceback (most recent call last):
  File "/home/runner/DjangoGPTChatHistory/.pythonlibs/lib/python3.11/site-packages/flask/app.py", line 1473, in wsgi_app
    response = self.full_dispatch_request()
               ^^^^^^^^^^^^^^^^^^^^^^^^^^^^
  File "/home/runner/DjangoGPTChatHistory/.pythonlibs/lib/python3.11/site-packages/flask/app.py", line 882, in full_dispatch_request
    rv = self.handle_user_exception(e)
         ^^^^^^^^^^^^^^^^^^^^^^^^^^^^^
  File "/home/runner/DjangoGPTChatHistory/.pythonlibs/lib/python3.11/site-packages/flask/app.py", line 880, in full_dispatch_request
    rv = self.dispatch_request()
         ^^^^^^^^^^^^^^^^^^^^^^^
  File "/home/runner/DjangoGPTChatHistory/.pythonlibs/lib/python3.11/site-packages/flask/app.py", line 865, in dispatch_request
    return self.ensure_sync(self.view_functions[rule.endpoint])(**view_args)  # type: ignore[no-any-return]
           ^^^^^^^^^^^^^^^^^^^^^^^^^^^^^^^^^^^^^^^^^^^^^^^^^^^^^^^^^^^^^^^^^
  File "/home/runner/DjangoGPTChatHistory/routes.py", line 74, in login
    return render_template('login.html')
           ^^^^^^^^^^^^^^^^^^^^^^^^^^^^^
  File "/home/runner/DjangoGPTChatHistory/.pythonlibs/lib/python3.11/site-packages/flask/templating.py", line 150, in render_template
    return _render(app, template, context)
           ^^^^^^^^^^^^^^^^^^^^^^^^^^^^^^^
  File "/home/runner/DjangoGPTChatHistory/.pythonlibs/lib/python3.11/site-packages/flask/templating.py", line 131, in _render
    rv = template.render(context)
         ^^^^^^^^^^^^^^^^^^^^^^^^
  File "/home/runner/DjangoGPTChatHistory/.pythonlibs/lib/python3.11/site-packages/jinja2/environment.py", line 1304, in render
    self.environment.handle_exception()
  File "/home/runner/DjangoGPTChatHistory/.pythonlibs/lib/python3.11/site-packages/jinja2/environment.py", line 939, in handle_exception
    raise rewrite_traceback_stack(source=source)
  File "/home/runner/DjangoGPTChatHistory/templates/login.html", line 1, in top-level template code
    {% extends "base.html" %}
  File "/home/runner/DjangoGPTChatHistory/templates/base.html", line 44, in top-level template code
    {% block content %}{% endblock %}
    ^^^^^^^^^^^^^^^^^^^^^^^^^
  File "/home/runner/DjangoGPTChatHistory/templates/login.html", line 28, in block 'content'
    <a href="{{ url_for('forgot_password') }}">Forgot Password?</a>
    ^^^^^^^^^^^^^^^^^^^^^^^^^
  File "/home/runner/DjangoGPTChatHistory/.pythonlibs/lib/python3.11/site-packages/flask/app.py", line 1084, in url_for
    return self.handle_url_build_error(error, endpoint, values)
           ^^^^^^^^^^^^^^^^^^^^^^^^^^^^^^^^^^^^^^^^^^^^^^^^^^^^
  File "/home/runner/DjangoGPTChatHistory/.pythonlibs/lib/python3.11/site-packages/flask/app.py", line 1073, in url_for
    rv = url_adapter.build(  # type: ignore[union-attr]
         ^^^^^^^^^^^^^^^^^^^^^^^^^^^^^^^^^^^^^^^^^^^^^^
  File "/home/runner/DjangoGPTChatHistory/.pythonlibs/lib/python3.11/site-packages/werkzeug/routing/map.py", line 924, in build
    raise BuildError(endpoint, values, method, self)
werkzeug.routing.exceptions.BuildError: Could not build url for endpoint 'forgot_password'. Did you mean 'update_password' instead?
10.83.8.52 - - [26/Oct/2024:16:57:23 +0000] "GET /login?next=%2Fsettings HTTP/1.1" 500 265 "-" "Mozilla/5.0 (X11; Linux x86_64) AppleWebKit/537.36 (KHTML, like Gecko) HeadlessChrome/118.0.5993.88 Safari/537.36"