2024-10-26 22:08:44,388 ERROR: Exception on /login [GET] [in /home/runner/MyGPTApp/.pythonlibs/lib/python3.11/site-packages/flask/app.py:838]
Traceback (most recent call last):
  File "/home/runner/MyGPTApp/.pythonlibs/lib/python3.11/site-packages/flask/app.py", line 1473, in wsgi_app
    response = self.full_dispatch_request()
               ^^^^^^^^^^^^^^^^^^^^^^^^^^^^
  File "/home/runner/MyGPTApp/.pythonlibs/lib/python3.11/site-packages/flask/app.py", line 882, in full_dispatch_request
    rv = self.handle_user_exception(e)
         ^^^^^^^^^^^^^^^^^^^^^^^^^^^^^
  File "/home/runner/MyGPTApp/.pythonlibs/lib/python3.11/site-packages/flask/app.py", line 880, in full_dispatch_request
    rv = self.dispatch_request()
         ^^^^^^^^^^^^^^^^^^^^^^^
  File "/home/runner/MyGPTApp/.pythonlibs/lib/python3.11/site-packages/flask/app.py", line 865, in dispatch_request
    return self.ensure_sync(self.view_functions[rule.endpoint])(**view_args)  # type: ignore[no-any-return]
           ^^^^^^^^^^^^^^^^^^^^^^^^^^^^^^^^^^^^^^^^^^^^^^^^^^^^^^^^^^^^^^^^^
  File "/home/runner/MyGPTApp/.pythonlibs/lib/python3.11/site-packages/flask_limiter/extension.py", line 1303, in __inner
    return cast(R, flask.current_app.ensure_sync(obj)(*a, **k))
                   ^^^^^^^^^^^^^^^^^^^^^^^^^^^^^^^^^^^^^^^^^^^
  File "/home/runner/MyGPTApp/routes.py", line 72, in login
    return render_template('login.html')
           ^^^^^^^^^^^^^^^^^^^^^^^^^^^^^
  File "/home/runner/MyGPTApp/.pythonlibs/lib/python3.11/site-packages/flask/templating.py", line 150, in render_template
    return _render(app, template, context)
           ^^^^^^^^^^^^^^^^^^^^^^^^^^^^^^^
  File "/home/runner/MyGPTApp/.pythonlibs/lib/python3.11/site-packages/flask/templating.py", line 131, in _render
    rv = template.render(context)
         ^^^^^^^^^^^^^^^^^^^^^^^^
  File "/home/runner/MyGPTApp/.pythonlibs/lib/python3.11/site-packages/jinja2/environment.py", line 1304, in render
    self.environment.handle_exception()
  File "/home/runner/MyGPTApp/.pythonlibs/lib/python3.11/site-packages/jinja2/environment.py", line 939, in handle_exception
    raise rewrite_traceback_stack(source=source)
  File "/home/runner/MyGPTApp/templates/login.html", line 1, in top-level template code
    {% extends "base.html" %}
  File "/home/runner/MyGPTApp/templates/base.html", line 46, in top-level template code
    {% block content %}{% endblock %}
    ^^^^^^^^^^^^^^^^^^^^^^^^^
  File "/home/runner/MyGPTApp/templates/login.html", line 28, in block 'content'
    <a href="{{ url_for('forgot_password') }}">Forgot Password?</a>
    ^^^^^^^^^^^^^^^^^^^^^^^^^
  File "/home/runner/MyGPTApp/.pythonlibs/lib/python3.11/site-packages/flask/app.py", line 1084, in url_for
    return self.handle_url_build_error(error, endpoint, values)
           ^^^^^^^^^^^^^^^^^^^^^^^^^^^^^^^^^^^^^^^^^^^^^^^^^^^^
  File "/home/runner/MyGPTApp/.pythonlibs/lib/python3.11/site-packages/flask/app.py", line 1073, in url_for
    rv = url_adapter.build(  # type: ignore[union-attr]
         ^^^^^^^^^^^^^^^^^^^^^^^^^^^^^^^^^^^^^^^^^^^^^^
  File "/home/runner/MyGPTApp/.pythonlibs/lib/python3.11/site-packages/werkzeug/routing/map.py", line 924, in build
    raise BuildError(endpoint, values, method, self)
werkzeug.routing.exceptions.BuildError: Could not build url for endpoint 'forgot_password'. Did you mean 'update_password' instead?
2024-10-26 22:08:44,393 ERROR: Internal server error: 500 Internal Server Error: The server encountered an internal error and was unable to complete your request. Either the server is overloaded or there is an error in the application. [in /home/runner/MyGPTApp/routes.py:240]
2024-10-26 22:08:44,709 INFO: Application startup [in /home/runner/MyGPTApp/app.py:33]
2024-10-26 22:08:44,710 INFO: Extensions initialized successfully [in /home/runner/MyGPTApp/app.py:96]
2024-10-26 22:08:44,788 INFO: Application startup [in /home/runner/MyGPTApp/app.py:33]
2024-10-26 22:08:44,789 INFO: Extensions initialized successfully [in /home/runner/MyGPTApp/app.py:96]
2024-10-26 22:08:45,578 INFO: Database tables and indexes created successfully [in /home/runner/MyGPTApp/app.py:130]
2024-10-26 22:08:45,812 INFO: Database tables and indexes created successfully [in /home/runner/MyGPTApp/app.py:130]
